2023/11/25 00:00|Домашнее задание по теме "Сложные моменты и исключения в стеке вызовов функции".

def personal_sum(numbers):
    result = 0
    incorrect_data = 0
    for i in numbers:
        try:
            result += i
        except:
            print(f'Неверные данные: {i}')
            incorrect_data += 1

    data = [result, incorrect_data]
    return data

def calculate_average(numbers):
    try:
        return personal_sum(numbers)[0] / (len(numbers) - personal_sum(numbers)[1])
    except ZeroDivisionError:
        return '0'
    except TypeError:
        return None

print(f'Результат 1: {calculate_average("1, 2, 3")}')
print(f'Результат 2: {calculate_average([1, "Строка", 3, "Ещё Строка"])}')
print(f'Результат 3: {calculate_average(567)}')
print(f'Результат 4: {calculate_average([42, 15, 36, 13])}')
